Workbook

Sheet Dashboard
B1: PROJECT NAVIGATION | D1: ONLINE RETAIL | SALES & CUSTOMER ANALYSIS
B3: 1 · Dashboard
B4: 2 · Sales Analysis | D4: GROSS SALES | F4: AVG ORDER VALUE | H4: UNITS SOLD | J4: REPEAT CUSTOMER RATE | L4: REVERSAL VALUE | N4: UNIQUE PRODUCTS
B5: 3 · Monthly Analysis | D5: =SUM('Monthly Analysis'!$E$52:$E$64) -> 10666685 | F5: =SUM('Monthly Analysis'!$E$52:$E$64)/SUM('Monthly Analysis'!$F$52:$F$64) -> 534.40303 | H5: =SUM('Monthly Analysis'!$H$52:$H$64) -> 5588376 | J5: =SUMIF('Customer Analysis'!$M$52:$M$53,"Repeat",'Customer Analysis'!$N$52:$N$53)/SUM('Customer Analysis'!$N$52:$N$53) -> 0.65583218 | L5: =SUM('Returns & Cancellations'!$H$52:$H$64) -> 896812.49 | N5: ='Data Quality'!$E$41 -> 3922
B6: 4 · Country Analysis
B7: 5 · Product Analysis | D7: Eligible positive sales | F7: Gross sales ÷ orders | H7: Eligible positive sales | J7: Customers with 2+ orders | L7: =TEXT(SUM('Returns & Cancellations'!$H$52:$H$64)/SUM('Monthly Analysis'!$E$52:$E$64),"0.0%")&" of gross sales" -> 8.4% of gross sales | N7: Distinct stock codes sold
B8: 6 · Customer Analysis
B9: 7 · Returns & Cancellations
B10: 8 · Time Analysis
B11: 9 · Data Quality
B12: 10 · Data Dictionary
B13: 11 · Transaction Data

Sheet Sales Analysis
B1: PROJECT NAVIGATION | D1: SALES ANALYSIS | REVENUE & ORDER PERFORMANCE | V1: Country options
V2: All Countries
B3: 1 · Dashboard | D3: All Countries | V3: Australia
B4: 2 · Sales Analysis | D4: GROSS SALES | F4: ORDERS | H4: UNITS SOLD | J4: AVG ORDER VALUE | L4: REVERSAL VALUE | N4: NET SALES | V4: Austria
B5: 3 · Monthly Analysis | D5: =IF($D$3="All Countries",SUM($S$53:$S$90),SUMIF($R$53:$R$90,$D$3,$S$53:$S$90)) -> 10666685 | F5: =IF($D$3="All Countries",SUM($T$53:$T$90),SUMIF($R$53:$R$90,$D$3,$T$53:$T$90)) -> 19960 | H5: =IF($D$3="All Countries",SUM($U$53:$U$90),SUMIF($R$53:$R$90,$D$3,$U$53:$U$90)) -> 5588376 | J5: =IFERROR(D5/F5,0) -> 534.40303 | L5: =896812.49 -> 896812.49 | N5: =D5-L5 -> 9769872.1 | V5: Bahrain
B6: 4 · Country Analysis | V6: Belgium
B7: 5 · Product Analysis | D7: Eligible positive sales | F7: Distinct invoices; country-aware | H7: Positive-quantity units | J7: Gross sales ÷ orders | L7: Estimated cancellation/return value | N7: Gross sales less estimated reversals | V7: Brazil
B8: 6 · Customer Analysis | V8: Canada
B9: 7 · Returns & Cancellations | D9: KEY SALES INSIGHTS | V9: Channel Islands
B10: 8 · Time Analysis | D10: 1 | E10: Gross sales total £10,666,685 across 19,960 distinct eligible invoices; average order value is £534.40. | V10: Cyprus
B11: 9 · Data Quality | D11: 2 | E11: 3,922 distinct stock codes generated positive sales; units sold total 5,588,376. | V11: Czech Republic
B12: 10 · Data Dictionary | D12: 3 | E12: The top sales month is 2011-11 with £1,509,496 gross sales. | V12: Denmark
B13: 11 · Transaction Data | D13: 4 | E13: Reversal value is estimated from absolute quantity × unit price for negative-quantity/cancellation candidates; net sales here are an estimate. | V13: EIRE
V14: European Community
D15: VISUAL ANALYSIS | V15: Finland
V16: France
V17: Germany
V18: Greece
V19: Hong Kong
V20: Iceland
V21: Israel
V22: Italy
V23: Japan
V24: Lebanon
V25: Lithuania
V26: Malta
D27: MONTHLY SALES DATA TABLE | V27: Netherlands
D28: Month | E28: Gross Sales | F28: Orders | G28: Units Sold | H28: Average Order Value | I28: MoM Change | J28: Month | K28: Selected Sales | V28: Norway
D29: 2010-12 | E29: 823746.14 | F29: 1559 | G29: 359239 | H29: 528.3811 | J29: 2010-12 | K29: =IF($D$3="All Countries",E29,SUMIFS($X$53:$X$10000,$W$53:$W$10000,$D$3,$Y$53:$Y$10000,J29)) -> 823746.14
D30: 2011-01 | E30: 691364.56 | F30: 1086 | G30: 387785 | H30: 636.61562 | I30: -0.16070677 | J30: 2011-01 | K30: =IF($D$3="All Countries",E30,SUMIFS($X$53:$X$10000,$W$53:$W$10000,$D$3,$Y$53:$Y$10000,J30)) -> 691364.56
D31: 2011-02 | E31: 523631.89 | F31: 1100 | G31: 283555 | H31: 476.02899 | I31: -0.24261103 | J31: 2011-02 | K31: =IF($D$3="All Countries",E31,SUMIFS($X$53:$X$10000,$W$53:$W$10000,$D$3,$Y$53:$Y$10000,J31)) -> 523631.89
D32: 2011-03 | E32: 717639.36 | F32: 1454 | G32: 377526 | H32: 493.56215 | I32: 0.37050354 | J32: 2011-03 | K32: =IF($D$3="All Countries",E32,SUMIFS($X$53:$X$10000,$W$53:$W$10000,$D$3,$Y$53:$Y$10000,J32)) -> 717639.36
D33: 2011-04 | E33: 537808.62 | F33: 1246 | G33: 308815 | H33: 431.62811 | I33: -0.2505865 | J33: 2011-04 | K33: =IF($D$3="All Countries",E33,SUMIFS($X$53:$X$10000,$W$53:$W$10000,$D$3,$Y$53:$Y$10000,J33)) -> 537808.62
D34: 2011-05 | E34: 770536.02 | F34: 1681 | G34: 395738 | H34: 458.37955 | I34: 0.43273274 | J34: 2011-05 | K34: =IF($D$3="All Countries",E34,SUMIFS($X$53:$X$10000,$W$53:$W$10000,$D$3,$Y$53:$Y$10000,J34)) -> 770536.02
D35: 2011-06 | E35: 761739.9 | F35: 1533 | G35: 389213 | H35: 496.89491 | I35: -0.011415586 | J35: 2011-06 | K35: =IF($D$3="All Countries",E35,SUMIFS($X$53:$X$10000,$W$53:$W$10000,$D$3,$Y$53:$Y$10000,J35)) -> 761739.9
D36: 2011-07 | E36: 719221.19 | F36: 1475 | G36: 401759 | H36: 487.60759 | I36: -0.055817884 | J36: 2011-07 | K36: =IF($D$3="All Countries",E36,SUMIFS($X$53:$X$10000,$W$53:$W$10000,$D$3,$Y$53:$Y$10000,J36)) -> 719221.19
D37: 2011-08 | E37: 759138.38 | F37: 1361 | G37: 421770 | H37: 557.77985 | I37: 0.055500574 | J37: 2011-08 | K37: =IF($D$3="All Countries",E37,SUMIFS($X$53:$X$10000,$W$53:$W$10000,$D$3,$Y$53:$Y$10000,J37)) -> 759138.38
D38: 2011-09 | E38: 1058590.2 | F38: 1837 | G38: 570820 | H38: 576.2603 | I38: 0.39446272 | J38: 2011-09 | K38: =IF($D$3="All Countries",E38,SUMIFS($X$53:$X$10000,$W$53:$W$10000,$D$3,$Y$53:$Y$10000,J38)) -> 1058590.2
D39: 2011-10 | E39: 1154979.3 | F39: 2040 | G39: 623401 | H39: 566.16632 | I39: 0.091054244 | J39: 2011-10 | K39: =IF($D$3="All Countries",E39,SUMIFS($X$53:$X$10000,$W$53:$W$10000,$D$3,$Y$53:$Y$10000,J39)) -> 1154979.3
D40: 2011-11 | E40: 1509496.3 | F40: 2769 | G40: 754507 | H40: 545.14133 | I40: 0.30694665 | J40: 2011-11 | K40: =IF($D$3="All Countries",E40,SUMIFS($X$53:$X$10000,$W$53:$W$10000,$D$3,$Y$53:$Y$10000,J40)) -> 1509496.3
...

Sheet Monthly Analysis
B1: PROJECT NAVIGATION | D1: MONTHLY PERFORMANCE
B3: 1 · Dashboard
B4: 2 · Sales Analysis | D4: TOTAL GROSS SALES | F4: AVG MONTHLY SALES | H4: PEAK MONTH | J4: LOWEST MONTH | L4: TOTAL ORDERS | N4: AVG ORDER VALUE
B5: 3 · Monthly Analysis | D5: =SUM(E52:E64) -> 10666685 | F5: =AVERAGE(E52:E64) -> 820514.2 | H5: =INDEX(D52:D64,MATCH(MAX(E52:E64),E52:E64,0)) -> 2011-11 | J5: =INDEX(D52:D64,MATCH(MIN(E52:E64),E52:E64,0)) -> 2011-02 | L5: =SUM(F52:F64) -> 19960 | N5: =SUM(E52:E64)/SUM(F52:F64) -> 534.40303
B6: 4 · Country Analysis
B7: 5 · Product Analysis | D7: =COUNTA(D52:D64)&" months of data" -> 13 months of data | F7: Includes partial Dec 2011 | H7: =TEXT(MAX(E52:E64),"$#,##0")&" gross sales" -> $1,509,496 gross sales | J7: =TEXT(MIN(E52:E64),"$#,##0")&" gross sales" -> $523,632 gross sales | L7: Distinct invoices | N7: Gross sales ÷ orders
B8: 6 · Customer Analysis
B9: 7 · Returns & Cancellations | D9: KEY BUSINESS INSIGHTS
B10: 8 · Time Analysis | D10: 1 | E10: Peak month is 2011-11 ($1.51M); the weakest month is 2011-02 ($0.52M) — a 2.9x swing across the year.
B11: 9 · Data Quality | D11: 2 | E11: Sales build through autumn: Sep, Oct and Nov 2011 grew +39%, +9% and +31% month-on-month ahead of the Christmas peak.
B12: 10 · Data Dictionary | D12: 3 | E12: 2011-12 is a partial month (data ends 09 Dec 2011), so its -58% MoM drop is not a true decline.
B13: 11 · Transaction Data | D13: 4 | E13: Every 2011 quarter beat the one before it: 2011Q4 reached $3.30M, 1.7x 2011Q1, even with December incomplete.
D15: VISUAL ANALYSIS
D50: MONTHLY DATA TABLE
D51: Month | E51: Gross Sales | F51: Orders | G51: Customers | H51: Units Sold | I51: Average Order Value | J51: MoM Sales Change
D52: 2010-12 | E52: 823746.14 | F52: 1559 | G52: 885 | H52: 359239 | I52: 528.3811
D53: 2011-01 | E53: 691364.56 | F53: 1086 | G53: 741 | H53: 387785 | I53: 636.61562 | J53: -0.16070677
D54: 2011-02 | E54: 523631.89 | F54: 1100 | G54: 758 | H54: 283555 | I54: 476.02899 | J54: -0.24261103
D55: 2011-03 | E55: 717639.36 | F55: 1454 | G55: 974 | H55: 377526 | I55: 493.56215 | J55: 0.37050354
D56: 2011-04 | E56: 537808.62 | F56: 1246 | G56: 856 | H56: 308815 | I56: 431.62811 | J56: -0.2505865
D57: 2011-05 | E57: 770536.02 | F57: 1681 | G57: 1056 | H57: 395738 | I57: 458.37955 | J57: 0.43273274
D58: 2011-06 | E58: 761739.9 | F58: 1533 | G58: 991 | H58: 389213 | I58: 496.89491 | J58: -0.011415586
D59: 2011-07 | E59: 719221.19 | F59: 1475 | G59: 949 | H59: 401759 | I59: 487.60759 | J59: -0.055817884
D60: 2011-08 | E60: 759138.38 | F60: 1361 | G60: 935 | H60: 421770 | I60: 557.77985 | J60: 0.055500574
D61: 2011-09 | E61: 1058590.2 | F61: 1837 | G61: 1266 | H61: 570820 | I61: 576.2603 | J61: 0.39446272
D62: 2011-10 | E62: 1154979.3 | F62: 2040 | G62: 1364 | H62: 623401 | I62: 566.16632 | J62: 0.091054244
D63: 2011-11 | E63: 1509496.3 | F63: 2769 | G63: 1664 | H63: 754507 | I63: 545.14133 | J63: 0.30694665
D64: 2011-12 | E64: 638792.68 | F64: 819 | G64: 615 | H64: 314248 | I64: 779.96664 | J64: -0.57681733
D67: QUARTERLY SUMMARY
D68: Quarter | E68: Gross Sales | F68: Orders | G68: Customers | H68: Units Sold
D69: 2010Q4 | E69: 823746.14 | F69: 1559 | G69: 885 | H69: 359239
D70: 2011Q1 | E70: 1932635.8 | F70: 3640 | G70: 1776 | H70: 1048866
D71: 2011Q2 | E71: 2070084.5 | F71: 4460 | G71: 1991 | H71: 1093766
D72: 2011Q3 | E72: 2536949.7 | F72: 4673 | G72: 2161 | H72: 1394349
D73: 2011Q4 | E73: 3303268.3 | F73: 5628 | G73: 2560 | H73: 1692156

Sheet Country Analysis
B1: PROJECT NAVIGATION | D1: COUNTRY PERFORMANCE
B3: 1 · Dashboard
B4: 2 · Sales Analysis | D4: TOTAL GROSS SALES | E4: COUNTRIES SERVED | G4: TOP COUNTRY | I4: SALES OUTSIDE TOP COUNTRY | K4: TOP 5 COUNTRIES SHARE | M4: AVG ORDER VALUE
B5: 3 · Monthly Analysis | D5: =SUM(E52:E89) -> 10666685 | E5: =COUNTA(D52:D89) -> 38 | G5: =INDEX(D52:D89,MATCH(MAX(E52:E89),E52:E89,0)) -> United Kingdom | I5: =SUM(E52:E89)-MAX(E52:E89) -> 1641462.5 | K5: =SUM(E52:E56)/SUM(E52:E89) -> 0.94056448 | M5: =SUM(E52:E89)/SUM(F52:F89) -> 534.40303
B6: 4 · Country Analysis
B7: 5 · Product Analysis | D7: =COUNTA(D52:D89)&" countries" -> 38 countries | E7: With eligible sales | G7: =TEXT(MAX(E52:E89)/SUM(E52:E89),"0.0%")&" of gross sales" -> 84.6% of gross sales | I7: =TEXT(1-MAX(E52:E89)/SUM(E52:E89),"0.0%")&" of gross sales" -> 15.4% of gross sales | K7: Share of gross sales | M7: Gross sales ÷ orders
B8: 6 · Customer Analysis
B9: 7 · Returns & Cancellations | D9: KEY BUSINESS INSIGHTS
B10: 8 · Time Analysis | D10: 1 | E10: United Kingdom generates 84.6% of gross sales ($9.03M) from 3,920 customers — the business is heavily UK-centred.
B11: 9 · Data Quality | D11: 2 | E11: The next largest markets are Netherlands ($285K), EIRE ($283K) and Germany ($229K).
B12: 10 · Data Dictionary | D12: 3 | E12: EIRE and the Netherlands sell $283K+ to just 3 and 9 customers — a few large wholesale accounts, not broad demand.
B13: 11 · Transaction Data | D13: 4 | E13: Among markets with 50+ orders, Netherlands has the highest order value ($3,037) vs $501 in the UK.
D15: VISUAL ANALYSIS
D50: COUNTRY DATA TABLE
D51: Country | E51: Gross Sales | F51: Orders | G51: Customers | H51: Units Sold | I51: Sales Share | J51: Average Order Value | L51: Segment | M51: Gross Sales | N51: Share
D52: United Kingdom | E52: 9025222.1 | F52: 18019 | G52: 3920 | H52: 4662390 | I52: 0.84611315 | J52: 500.87253 | L52: =D52 -> United Kingdom | M52: =E52 -> 9025222.1 | N52: =M52/SUM(M52:M57) -> 0.84611315
D53: Netherlands | E53: 285446.34 | F53: 94 | G53: 9 | H53: 200361 | I53: 0.02676055 | J53: 3036.6632 | L53: =D53 -> Netherlands | M53: =E53 -> 285446.34 | N53: =M53/SUM(M52:M57) -> 0.02676055
D54: EIRE | E54: 283453.96 | F54: 288 | G54: 3 | H54: 147173 | I54: 0.026573764 | J54: 984.21514 | L54: =D54 -> EIRE | M54: =E54 -> 283453.96 | N54: =M54/SUM(M52:M57) -> 0.026573764
D55: Germany | E55: 228867.14 | F55: 457 | G55: 94 | H55: 119261 | I55: 0.021456258 | J55: 500.80337 | L55: =D55 -> Germany | M55: =E55 -> 228867.14 | N55: =M55/SUM(M52:M57) -> 0.021456258
D56: France | E56: 209715.11 | F56: 392 | G56: 87 | H56: 112103 | I56: 0.019660759 | J56: 534.98753 | L56: =D56 -> France | M56: =E56 -> 209715.11 | N56: =M56/SUM(M52:M57) -> 0.019660759
D57: Australia | E57: 138521.31 | F57: 57 | G57: 9 | H57: 83901 | I57: 0.012986351 | J57: 2430.1984 | L57: All other countries | M57: =SUM(E52:E89)-SUM(M52:M56) -> 633979.91 | N57: =M57/SUM(M52:M57) -> 0.059435517
D58: Spain | E58: 61577.11 | F58: 90 | G58: 30 | H58: 27940 | I58: 0.0057728444 | J58: 684.19011
D59: Switzerland | E59: 57089.9 | F59: 54 | G59: 21 | H59: 30629 | I59: 0.0053521692 | J59: 1057.2204 | L59: Top 5 + Others feeds the share chart (formulas).
D60: Belgium | E60: 41196.34 | F60: 98 | G60: 25 | H60: 23237 | I60: 0.0038621504 | J60: 420.37082
D61: Sweden | E61: 38378.33 | F61: 36 | G61: 8 | H61: 36083 | I61: 0.0035979624 | J61: 1066.0647
D62: Japan | E62: 37416.37 | F62: 19 | G62: 8 | H62: 26016 | I62: 0.0035077788 | J62: 1969.2826
D63: Norway | E63: 36165.44 | F63: 36 | G63: 10 | H63: 19336 | I63: 0.0033905043 | J63: 1004.5956
D64: Portugal | E64: 33747.1 | F64: 58 | G64: 19 | H64: 16258 | I64: 0.0031637853 | J64: 581.84655
D65: Finland | E65: 22546.08 | F65: 41 | G65: 12 | H65: 10704 | I65: 0.0021136915 | J65: 549.90439
D66: Singapore | E66: 21279.29 | F66: 7 | G66: 1 | H66: 5241 | I66: 0.0019949301 | J66: 3039.8986
D67: Channel Islands | E67: 20450.44 | F67: 26 | G67: 9 | H67: 9491 | I67: 0.0019172255 | J67: 786.55538
D68: Denmark | E68: 18955.34 | F68: 18 | G68: 9 | H68: 8235 | I68: 0.0017770601 | J68: 1053.0744
D69: Italy | E69: 17483.24 | F69: 38 | G69: 14 | H69: 8112 | I69: 0.001639051 | J69: 460.08526
D70: Hong Kong | E70: 15691.8 | F70: 11 | G70: 0 | H70: 4773 | I70: 0.0014711038 | J70: 1426.5273
D71: Cyprus | E71: 13590.38 | F71: 16 | G71: 8 | H71: 6361 | I71: 0.001274096 | J71: 849.39875
... D89: Saudi Arabia | E89: 145.92 | F89: 1 | G89: 1 | H89: 80 | I89: 1.3679977e-05 | J89: 145.92
D91: Country performance is ranked by gross sales. The full country list is included up to 100 rows; the dataset typically contains far fewer.

Sheet Product Analysis
B1: PROJECT NAVIGATION | D1: PRODUCT PERFORMANCE
B3: 1 · Dashboard
B4: 2 · Sales Analysis | D4: TOP PRODUCT BY GROSS SALES | F4: TOP 10 SHARE OF SALES | H4: TOP 200 SHARE OF SALES | J4: UNITS SOLD (TOP 200) | L4: AVG SALES PER PRODUCT
B5: 3 · Monthly Analysis | D5: =INDEX(E52:E251,MATCH(MAX(F52:F251),F52:F251,0)) -> DOTCOM POSTAGE | F5: =SUM(F52:F61)/SUM('Monthly Analysis'!$E$52:$E$64) -> 0.10802474 | H5: =SUM(F52:F251)/SUM('Monthly Analysis'!$E$52:$E$64) -> 0.46907669 | J5: =SUM(G52:G251) -> 1871102 | L5: =SUM(F52:F251)/COUNTA(D52:D251) -> 25017.465
B6: 4 · Country Analysis
B7: 5 · Product Analysis | D7: ="Stock code "&INDEX(D52:D251,MATCH(MAX(F52:F251),F52:F251,0))&" · "&TEXT(MAX(F52:F251),"$#,##0") -> Stock code DOT · $206,249 | F7: Share of total gross sales | H7: Share of total gross sales | J7: Units across listed products | L7: Across top 200 products
B8: 6 · Customer Analysis
B9: 7 · Returns & Cancellations | D9: KEY BUSINESS INSIGHTS
B10: 8 · Time Analysis | D10: 1 | E10: DOTCOM POSTAGE ranks #1 at $206K from 706 orders and 1 customer — it is a postage/service line, not merchandise.
B11: 9 · Data Quality | D11: 2 | E11: PAPER CRAFT , LITTLE BIRDIE ($168K) comes from 1 order and 1 customer (80,995 units) — a one-off bulk order that inflates product rankings.
B12: 10 · Data Dictionary | D12: 3 | E12: The best genuine sellers are REGENCY CAKESTAND 3 TIER ($174K) and WHITE HANGING HEART T-LIGHT HOLDER ($104K), each bought by hundreds of customers.
B13: 11 · Transaction Data | D13: 4 | E13: The top 10 products contribute 10.8% of gross sales — revenue is spread widely across the catalogue.
D15: VISUAL ANALYSIS
D50: PRODUCT DATA TABLE (TOP 200)
D51: Stock Code | E51: Description | F51: Gross Sales | G51: Units Sold | H51: Orders | I51: Customers | J51: Sales Share
D52: DOT | E52: DOTCOM POSTAGE | F52: 206248.77 | G52: 706 | H52: 706 | I52: 1 | J52: 0.01933579
D53: 22423 | E53: REGENCY CAKESTAND 3 TIER | F53: 174484.74 | G53: 13879 | H53: 1988 | I53: 881 | J53: 0.016357917
D54: 23843 | E54: PAPER CRAFT , LITTLE BIRDIE | F54: 168469.6 | G54: 80995 | H54: 1 | I54: 1 | J54: 0.015793999
D55: 85123A | E55: WHITE HANGING HEART T-LIGHT HOLDER | F55: 104340.29 | G55: 37599 | H55: 2189 | I55: 856 | J55: 0.0097818858
D56: 47566 | E56: PARTY BUNTING | F56: 99504.33 | G56: 18295 | H56: 1685 | I56: 708 | J56: 0.0093285153
D57: 85099B | E57: JUMBO BAG RED RETROSPOT | F57: 94340.05 | G57: 48474 | H57: 2089 | I57: 635 | J57: 0.0088443649
D58: 23166 | E58: MEDIUM CERAMIC TOP STORAGE JAR | F58: 81700.92 | G58: 78033 | H58: 247 | I58: 138 | J58: 0.0076594484
D59: M | E59: Manual | F59: 78110.27 | G59: 7224 | H59: 289 | I59: 197 | J59: 0.0073228255
D60: POST | E60: POSTAGE | F60: 78101.88 | G60: 3150 | H60: 1126 | I60: 331 | J60: 0.007322039
D61: 23084 | E61: RABBIT NIGHT LIGHT | F61: 66964.99 | G61: 30788 | H61: 994 | I61: 450 | J61: 0.0062779573
D62: 22086 | E62: PAPER CHAIN KIT 50'S CHRISTMAS | F62: 64952.29 | G62: 19355 | H62: 1160 | I62: 613 | J62: 0.006089267
D63: 84879 | E63: ASSORTED COLOUR BIRD ORNAMENT | F63: 59094.93 | G63: 36461 | H63: 1455 | I63: 678 | J63: 0.0055401404
... D251: 23170 | E251: REGENCY TEA PLATE ROSES | F251: 11117.05 | G251: 6869 | H251: 445 | I251: 224 | J251: 0.0010422217
D253: Top 200 product descriptions/stock codes by gross sales are displayed. Descriptions are retained as provided by the source.

Sheet Customer Analysis
B1: PROJECT NAVIGATION | D1: CUSTOMER PERFORMANCE
B3: 1 · Dashboard
B4: 2 · Sales Analysis | D4: IDENTIFIED CUSTOMERS | F4: REPEAT CUSTOMER RATE | H4: REPEAT SHARE OF SALES | J4: AVG SALES PER CUSTOMER | L4: TOP CUSTOMER SALES | N4: TOP 10 CUSTOMERS SHARE
B5: 3 · Monthly Analysis | D5: =SUM(N52:N53) -> 4338 | F5: =SUMIF(M52:M53,"Repeat",N52:N53)/SUM(N52:N53) -> 0.65583218 | H5: =SUMIF(M52:M53,"Repeat",O52:O53)/SUM(O52:O53) -> 0.93084014 | J5: =SUM(O52:O53)/SUM(N52:N53) -> 2054.2665 | L5: =MAX(E52:E551) -> 280206.02 | N5: =SUM(E52:E61)/SUM(O52:O53) -> 0.17261881
B6: 4 · Country Analysis
B7: 5 · Product Analysis | D7: With a CustomerID | F7: 2+ distinct orders | H7: Of identified-customer sales | J7: Identified customers | L7: ="Customer "&INDEX(D52:D551,MATCH(MAX(E52:E551),E52:E551,0)) -> Customer 14646 | N7: Of identified-customer sales
B8: 6 · Customer Analysis
B9: 7 · Returns & Cancellations | D9: KEY BUSINESS INSIGHTS
B10: 8 · Time Analysis | D10: 1 | E10: 2,845 of 4,338 identified customers (65.6%) are repeat buyers and generate 93.1% of identified-customer sales.
B11: 9 · Data Quality | D11: 2 | E11: One-time customers are 34.4% of the base but only 6.9% of sales — converting them to a second order is the clearest growth lever.
B12: 10 · Data Dictionary | D12: 3 | E12: The top 10 customers contribute 17.3% of identified sales; the largest, #14646, spent $280K.
B13: 11 · Transaction Data | D13: 4 | E13: Average spend per customer is $2,054, but the leaders spend 50-100x that — a clear VIP segment worth protecting.
D15: VISUAL ANALYSIS
D50: CUSTOMER DATA TABLE (TOP 500)
D51: Customer ID | E51: Gross Sales | F51: Orders | G51: Units Sold | H51: First Purchase | I51: Last Purchase | J51: Average Order Value | K51: Customer Type | M51: Customer Type | N51: Customers | O51: Gross Sales
D52: 14646 | E52: 280206.02 | F52: 73 | G52: 196915 | H52: 40532.423 | I52: 40885.508 | J52: 3838.4386 | K52: Repeat | M52: One-time | N52: 1493 | O52: 616311.73
D53: 18102 | E53: 259657.3 | F53: 60 | G53: 64124 | H53: 40519.696 | I53: 40886.493 | J53: 4327.6217 | K53: Repeat | M53: Repeat | N53: 2845 | O53: 8295096.2
D54: 17450 | E54: 194550.79 | F54: 46 | G54: 69993 | H54: 40519.391 | I54: 40878.562 | J54: 4229.365 | K54: Repeat
D55: 16446 | E55: 168472.5 | F55: 2 | G55: 80997 | H55: 40681.411 | I55: 40886.385 | J55: 84236.25 | K55: Repeat | M55: Customer-type summary feeds the charts.
D56: 14911 | E56: 143825.06 | F56: 201 | G56: 80265 | H56: 40513.587 | I56: 40885.662 | J56: 715.54756 | K56: Repeat
D57: 12415 | E57: 124914.53 | F57: 21 | G57: 77374 | H57: 40549.467 | I57: 40862.599 | J57: 5948.311 | K57: Repeat
D58: 14156 | E58: 117379.63 | F58: 55 | G58: 57885 | H58: 40515.492 | I58: 40877.454 | J58: 2134.1751 | K58: Repeat
D59: 17511 | E59: 91062.38 | F59: 31 | G59: 64549 | H59: 40513.43 | I59: 40884.425 | J59: 2937.4961 | K59: Repeat
D60: 16029 | E60: 81024.84 | F60: 63 | G60: 40208 | H60: 40513.415 | I60: 40848.435 | J60: 1286.1086 | K60: Repeat
D61: 12346 | E61: 77183.6 | F61: 1 | G61: 74215 | H61: 40561.417 | I61: 40561.417 | J61: 77183.6 | K61: One-time
D62: 16684 | E62: 66653.56 | F62: 28 | G62: 50255 | H62: 40528.732 | I62: 40882.588 | J62: 2380.4843 | K62: Repeat
D63: 14096 | E63: 65164.79 | F63: 17 | G63: 16352 | H63: 40785.451 | I63: 40882.72 | J63: 3833.2229 | K63: Repeat
D64: 13694 | E64: 65039.62 | F64: 50 | G64: 63312 | H64: 40513.508 | I64: 40883.397 | J64: 1300.7924 | K64: Repeat
D65: 15311 | E65: 60767.9 | F65: 91 | G65: 38194 | H65: 40513.403 | I65: 40886.5 | J65: 667.77912 | K65: Repeat
D66: 13089 | E66: 58825.83 | F66: 97 | G66: 31070 | H66: 40517.435 | I66: 40884.376 | J66: 606.45186 | K66: Repeat
D67: 17949 | E67: 58510.48 | F67: 45 | G67: 30546 | H67: 40515.55 | I67: 40885.782 | J67: 1300.2329 | K67: Repeat
... D551: 12480 | E551: 3281.63 | F551: 4 | G551: 1707 | H551: 40550.644 | I551: 40858.619 | J551: 820.4075 | K551: Repeat
D553: Customers without CustomerID are not identifiable and are excluded from customer-level summaries, but their eligible sales remain in gross sales.

Sheet Returns & Cancellations
B1: PROJECT NAVIGATION | D1: RETURNS & CANCELLATIONS
B3: 1 · Dashboard
B4: 2 · Sales Analysis | D4: TOTAL REVERSAL VALUE | F4: REVERSAL RATE | H4: REVERSAL INVOICES | J4: REVERSAL LINES | L4: PEAK REVERSAL MONTH | N4: AVG MONTHLY REVERSALS
B5: 3 · Monthly Analysis | D5: =SUM(H52:H64) -> 896812.49 | F5: =SUM(H52:H64)/SUM('Monthly Analysis'!$E$52:$E$64) -> 0.08407603 | H5: =SUM(F52:F64) -> 5172 | J5: =SUM(E52:E64) -> 10624 | L5: =INDEX(D52:D64,MATCH(MAX(H52:H64),H52:H64,0)) -> 2011-12 | N5: =AVERAGE(H52:H64) -> 68985.576
B6: 4 · Country Analysis
B7: 5 · Product Analysis | D7: Cancellations & returns | F7: Of total gross sales | H7: Distinct invoices | J7: Transaction lines | L7: =TEXT(MAX(H52:H64),"$#,##0")&" reversed" -> $205,125 reversed | N7: Reversal value per month
B8: 6 · Customer Analysis
B9: 7 · Returns & Cancellations | D9: KEY BUSINESS INSIGHTS
B10: 8 · Time Analysis | D10: 1 | E10: Reversals total $897K — 8.4% of gross sales — from 5,172 invoices; cancellations drive all of the value.
B11: 9 · Data Quality | D11: 2 | E11: 2011-12 is the peak month at $205K even though December 2011 is incomplete — the single largest reversal month.
B12: 10 · Data Dictionary | D12: 3 | E12: 1,336 negative-quantity lines carry no price ($0 reversal value) — stock adjustments rather than customer refunds.
B13: 11 · Transaction Data | D13: 4 | E13: Reversal lines peak in 2011-10 (1,346 lines) ahead of Christmas, while the value peak comes from a handful of large cancellations.
D15: VISUAL ANALYSIS
D50: REVERSAL DATA TABLE
D51: Month | E51: Reversal Lines | F51: Reversal Invoices | G51: Reversal Units | H51: Reversal Value | J51: Month | K51: Reversal Value | L51: Gross Sales | M51: Reversal Rate
D52: 2010-12 | E52: 798 | F52: 396 | G52: 20088 | H52: 74789.12 | J52: =D52 -> 2010-12 | K52: =H52 -> 74789.12 | L52: =INDEX('Monthly Analysis'!$E$52:$E$64,MATCH(J52,'Monthly Analysis'!$D$52:$D$64,0)) -> 823746.14 | M52: =IF(L52=0,0,K52/L52) -> 0.090791466
D53: 2011-01 | E53: 797 | F53: 356 | G53: 88750 | H53: 131364.3 | J53: =D53 -> 2011-01 | K53: =H53 -> 131364.3 | L53: =INDEX('Monthly Analysis'!$E$52:$E$64,MATCH(J53,'Monthly Analysis'!$D$52:$D$64,0)) -> 691364.56 | M53: =IF(L53=0,0,K53/L53) -> 0.19000728
D54: 2011-02 | E54: 523 | F54: 267 | G54: 8706 | H54: 25569.24 | J54: =D54 -> 2011-02 | K54: =H54 -> 25569.24 | L54: =INDEX('Monthly Analysis'!$E$52:$E$64,MATCH(J54,'Monthly Analysis'!$D$52:$D$64,0)) -> 523631.89 | M54: =IF(L54=0,0,K54/L54) -> 0.048830563
D55: 2011-03 | E55: 833 | F55: 452 | G55: 33078 | H55: 34372.28 | J55: =D55 -> 2011-03 | K55: =H55 -> 34372.28 | L55: =INDEX('Monthly Analysis'!$E$52:$E$64,MATCH(J55,'Monthly Analysis'!$D$52:$D$64,0)) -> 717639.36 | M55: =IF(L55=0,0,K55/L55) -> 0.047896314
D56: 2011-04 | E56: 745 | F56: 426 | G56: 23078 | H56: 44601.5 | J56: =D56 -> 2011-04 | K56: =H56 -> 44601.5 | L56: =INDEX('Monthly Analysis'!$E$52:$E$64,MATCH(J56,'Monthly Analysis'!$D$52:$D$64,0)) -> 537808.62 | M56: =IF(L56=0,0,K56/L56) -> 0.082931917
D57: 2011-05 | E57: 738 | F57: 431 | G57: 19034 | H57: 47202.51 | J57: =D57 -> 2011-05 | K57: =H57 -> 47202.51 | L57: =INDEX('Monthly Analysis'!$E$52:$E$64,MATCH(J57,'Monthly Analysis'!$D$52:$D$64,0)) -> 770536.02 | M57: =IF(L57=0,0,K57/L57) -> 0.061259317
D58: 2011-06 | E58: 818 | F58: 436 | G58: 52714 | H58: 70616.78 | J58: =D58 -> 2011-06 | K58: =H58 -> 70616.78 | L58: =INDEX('Monthly Analysis'!$E$52:$E$64,MATCH(J58,'Monthly Analysis'!$D$52:$D$64,0)) -> 761739.9 | M58: =IF(L58=0,0,K58/L58) -> 0.092704583
D59: 2011-07 | E59: 802 | F59: 387 | G59: 16423 | H59: 37921.08 | J59: =D59 -> 2011-07 | K59: =H59 -> 37921.08 | L59: =INDEX('Monthly Analysis'!$E$52:$E$64,MATCH(J59,'Monthly Analysis'!$D$52:$D$64,0)) -> 719221.19 | M59: =IF(L59=0,0,K59/L59) -> 0.052725198
D60: 2011-08 | E60: 718 | F60: 328 | G60: 18817 | H60: 54333.75 | J60: =D60 -> 2011-08 | K60: =H60 -> 54333.75 | L60: =INDEX('Monthly Analysis'!$E$52:$E$64,MATCH(J60,'Monthly Analysis'!$D$52:$D$64,0)) -> 759138.38 | M60: =IF(L60=0,0,K60/L60) -> 0.071572919
D61: 2011-09 | E61: 903 | F61: 431 | G61: 25599 | H61: 38902.55 | J61: =D61 -> 2011-09 | K61: =H61 -> 38902.55 | L61: =INDEX('Monthly Analysis'!$E$52:$E$64,MATCH(J61,'Monthly Analysis'!$D$52:$D$64,0)) -> 1058590.2 | M61: =IF(L61=0,0,K61/L61) -> 0.036749397
D62: 2011-10 | E62: 1346 | F62: 508 | G62: 58213 | H62: 84274.63 | J62: =D62 -> 2011-10 | K62: =H62 -> 84274.63 | L62: =INDEX('Monthly Analysis'!$E$52:$E$64,MATCH(J62,'Monthly Analysis'!$D$52:$D$64,0)) -> 1154979.3 | M62: =IF(L62=0,0,K62/L62) -> 0.072966355
D63: 2011-11 | E63: 1213 | F63: 578 | G63: 31312 | H63: 47740.08 | J63: =D63 -> 2011-11 | K63: =H63 -> 47740.08 | L63: =INDEX('Monthly Analysis'!$E$52:$E$64,MATCH(J63,'Monthly Analysis'!$D$52:$D$64,0)) -> 1509496.3 | M63: =IF(L63=0,0,K63/L63) -> 0.031626496
D64: 2011-12 | E64: 390 | F64: 176 | G64: 88719 | H64: 205124.67 | J64: =D64 -> 2011-12 | K64: =H64 -> 205124.67 | L64: =INDEX('Monthly Analysis'!$E$52:$E$64,MATCH(J64,'Monthly Analysis'!$D$52:$D$64,0)) -> 638792.68 | M64: =IF(L64=0,0,K64/L64) -> 0.32111306
J65: Reversal rate = reversal value ÷ gross sales for the same month (formulas).
D66: REVERSAL TYPE SUMMARY
D67: Invoice Type | E67: Lines | F67: Invoices | G67: Units | H67: Reversal Value
D68: Cancellation | E68: 9288 | F68: 3836 | G68: 277574 | H68: 896812.49
D69: Return / negative quantity | E69: 1336 | F69: 1336 | G69: 206957 | H69: 0
D71: Rows are flagged when InvoiceNo begins with C or Quantity is negative. The source does not provide a separate refund/return authorization ledger.

Sheet Time Analysis
B1: PROJECT NAVIGATION | D1: TIME & ORDER PATTERNS
B3: 1 · Dashboard
B4: 2 · Sales Analysis | D4: PEAK DAY | F4: PEAK DAY SALES | H4: PEAK HOUR (SALES) | J4: PEAK HOUR SALES | L4: BUSIEST HOUR (ORDERS) | N4: WEEKEND SHARE OF SALES
B5: 3 · Monthly Analysis | D5: =INDEX(D52:D58,MATCH(MAX(E52:E58),E52:E58,0)) -> Thursday | F5: =MAX(E52:E58) -> 2203161.2 | H5: =INDEX(I52:I66,MATCH(MAX(J52:J66),J52:J66,0)) -> 10 | J5: =MAX(J52:J66) -> 1446742.7 | L5: =INDEX(I52:I66,MATCH(MAX(K52:K66),K52:K66,0)) -> 12 | N5: =(SUMIF(D52:D58,"Saturday",E52:E58)+SUMIF(D52:D58,"Sunday",E52:E58))/SUM(E52:E58) -> 0.076296211
B6: 4 · Country Analysis
B7: 5 · Product Analysis | D7: =TEXT(MAX(E52:E58),"$#,##0")&" gross sales" -> $2,203,161 gross sales | F7: Highest weekday total | H7: =TEXT(MAX(J52:J66),"$#,##0")&" gross sales" -> $1,446,743 gross sales | J7: Highest hourly total | L7: =TEXT(MAX(K52:K66),"#,##0")&" orders" -> 3,220 orders | N7: Saturday + Sunday
B8: 6 · Customer Analysis
B9: 7 · Returns & Cancellations | D9: KEY BUSINESS INSIGHTS
B10: 8 · Time Analysis | D10: 1 | E10: Thursday is the strongest day ($2.20M) and Sunday the weakest trading day ($0.81M); there are no Saturday transactions in the source data.
B11: 9 · Data Quality | D11: 2 | E11: Sales peak at 10:00 ($1.45M), with 10:00-15:00 delivering the bulk of daily revenue.
B12: 10 · Data Dictionary | D12: 3 | E12: 12:00 is the busiest hour by order count (3,220 orders), slightly ahead of the sales peak.
B13: 11 · Transaction Data | D13: 4 | E13: Trading is concentrated in business hours: 91% of gross sales fall between 09:00 and 16:59.
D15: VISUAL ANALYSIS
D50: DAY & HOUR DATA TABLES
D51: Day of Week | E51: Gross Sales | F51: Orders | G51: Units Sold | I51: Hour | J51: Gross Sales | K51: Orders | L51: Units Sold
D52: Monday | E52: 1779575 | F52: 3126 | G52: 873332 | I52: 6 | J52: 4.25 | K52: 1 | L52: 1
D53: Tuesday | E53: 2178632.6 | F53: 3554 | G53: 1115208 | I53: 7 | J53: 31059.21 | K53: 29 | L53: 15370
D54: Wednesday | E54: 1851147.8 | F54: 3690 | G54: 1027431 | I54: 8 | J54: 283868.52 | K54: 566 | L54: 159097
D55: Thursday | E55: 2203161.2 | F55: 4246 | G55: 1209617 | I55: 9 | J55: 990267.82 | K55: 1484 | L55: 518098
D56: Friday | E56: 1840340.2 | F56: 3140 | G56: 891784 | I56: 10 | J56: 1446742.7 | K56: 2361 | L56: 813805
D57: Saturday | E57: 0 | F57: 0 | G57: 0 | I57: 11 | J57: 1239954.4 | K57: 2396 | L57: 674682
D58: Sunday | E58: 813827.61 | F58: 2204 | G58: 471004 | I58: 12 | J58: 1444245.9 | K58: 3220 | L58: 839523
I59: 13 | J59: 1265736.3 | K59: 2753 | L59: 706285
I60: 14 | J60: 1181812.4 | K60: 2457 | L60: 599220
I61: 15 | J61: 1352972.2 | K61: 2336 | L61: 628564
I62: 16 | J62: 754006.56 | K62: 1335 | L62: 331487
I63: 17 | J63: 461603.49 | K63: 667 | L63: 192975
I64: 18 | J64: 144813.05 | K64: 192 | L64: 66578
I65: 19 | J65: 50665.01 | K65: 146 | L65: 33104
I66: 20 | J66: 18932.76 | K66: 18 | L66: 9587
D68: Day-of-week and hourly summaries use the timestamp recorded in InvoiceDate; no timezone conversion is applied. Saturday is shown as zero: the source contains no Saturday transactions.

Sheet Data Quality
B1: PROJECT NAVIGATION | D1: DATA QUALITY & VALIDATION
B3: 1 · Dashboard
B4: 2 · Sales Analysis | D4: KEY BUSINESS INSIGHTS
B5: 3 · Monthly Analysis | D5: 1 | E5: Only 97.8% of source rows (530,104 of 541,909) qualify as positive sales; 11,805 rows are cancellations, returns or zero-price lines.
B6: 4 · Country Analysis | D6: 2 | E6: 135,080 rows (24.9%) have no CustomerID — they stay in sales totals but are excluded from customer-level analysis.
B7: 5 · Product Analysis | D7: 3 | E7: 5,268 exact duplicate rows are reported, not deleted, to preserve source fidelity; no rows have a missing InvoiceNo or date.
B8: 6 · Customer Analysis
B9: 7 · Returns & Cancellations | D9: VISUAL ANALYSIS
B10: 8 · Time Analysis
B11: 9 · Data Quality
B12: 10 · Data Dictionary
B13: 11 · Transaction Data
D27: VALIDATION CHECKS
D28: Check | E28: Result | F28: Interpretation
D29: Source rows | E29: 541909 | F29: All rows in the supplied source workbook; the full file is bundled separately and the transaction sheet is a preview.
D30: Rows with missing InvoiceNo | E30: 0 | F30: Not eligible for sales analysis; retained in the original source file.
D31: Rows with invalid/missing InvoiceDate | E31: 0 | F31: Not eligible for time-based sales analysis; retained in the original source file.
D32: Rows with missing CustomerID | E32: 135080 | F32: Included in sales totals when otherwise valid; excluded from customer-level distinct counts.
D33: Rows with missing Description | E33: 1454 | F33: Product analysis retains missing descriptions under blank label / stock code.
D34: Cancellation invoice rows (InvoiceNo starts C) | E34: 9288 | F34: Classified as cancellation/reversal rows.
D35: Negative quantity rows | E35: 10624 | F35: Classified as return/reversal candidates; not counted as positive sales.
D36: Zero/negative unit price rows | E36: 2517 | F36: Excluded from positive-sales KPI calculations; retained in the original source file.
D37: Exact duplicate source rows | E37: 5268 | F37: Reported, not automatically deleted to preserve source fidelity.
D38: Positive sale rows used for sales metrics | E38: 530104 | F38: Invoice not marked C, positive quantity and price, valid invoice number and date.
D39: Unique positive-sale invoices | E39: 19960 | F39: Distinct invoice numbers among eligible positive-sale rows.
D40: Unique customers with ID | E40: 4338 | F40: Distinct CustomerID among eligible positive-sale rows.
D41: Unique stock codes sold | E41: 3922 | F41: Distinct StockCode among eligible positive-sale rows.
D43: ROW COVERAGE
D44: Segment | E44: Rows
D45: Eligible positive-sale rows | E45: =E38 -> 530104
D46: Other rows (not used for sales metrics) | E46: =E29-E38 -> 11805

Sheet Data Dictionary
B1: PROJECT NAVIGATION | D1: DATA DICTIONARY & METHODOLOGY
B3: 1 · Dashboard
B4: 2 · Sales Analysis | D4: READ THIS FIRST
B5: 3 · Monthly Analysis | D5: 1 | E5: Currency: $ formatting is used as requested; source values are GBP and have NOT been converted with an exchange rate.
B6: 4 · Country Analysis | D6: 2 | E6: Net Sales = eligible gross sales less estimated cancellation/return value (definitions below).
B7: 5 · Product Analysis | D7: 3 | E7: 2011-12 is a partial month (data ends 09 Dec 2011), so December totals are not comparable with full months.
B8: 6 · Customer Analysis | D8: 4 | E8: Saturday has no transactions in the source data; Time Analysis shows it as zero.
B9: 7 · Returns & Cancellations | D9: 5 | E9: Analysis sheets use all 541,909 source rows; Transaction Data holds a 1,000-row preview only.
B10: 8 · Time Analysis
B11: 9 · Data Quality | D11: DEFINITIONS & METHODOLOGY
B12: 10 · Data Dictionary | D12: Topic | E12: Definition / Treatment
B13: 11 · Transaction Data | D13: Purpose | E13: Analyze the UCI Online Retail transaction dataset using an Excel-first reporting workbook.
D14: Source | E14: Online Retail.xlsx supplied in this conversation. The Transaction Data sheet shows a 1,000-row preview with derived analysis fields; the full source workbook is included separately in the project package.
D15: Gross Sales | E15: Sum of Quantity × UnitPrice for eligible positive-sale rows. Eligible means invoice does not start with C, Quantity > 0, UnitPrice > 0, and InvoiceNo and InvoiceDate are present/valid.
D16: Reversal Value | E16: Sum of absolute Quantity × UnitPrice for rows where InvoiceNo starts with C or Quantity is negative, provided UnitPrice > 0. This is an analytical estimate of cancelled/returned value; it is not a separate refund ledger.
D17: Net Sales | E17: Gross Sales less Reversal Value. Treat as a transaction-line net measure, not audited accounting revenue.
D18: Orders | E18: Distinct InvoiceNo among eligible positive-sale rows. Cancellation invoices are excluded from positive-sale orders.
D19: Customers | E19: Distinct non-null CustomerID among eligible positive-sale rows.
D20: Products | E20: Distinct non-null StockCode among eligible positive-sale rows.
D21: Average Order Value | E21: Gross Sales divided by eligible positive-sale invoices.
D22: Customer Repeat Rate | E22: Customers with more than one distinct eligible positive-sale invoice divided by customers with known CustomerID.
D23: Missing customer IDs | E23: Rows with missing CustomerID remain included in sales totals when otherwise eligible, but cannot contribute to customer-level unique counts.
D24: Duplicate rows | E24: Exact duplicate source rows are counted and reported but not deleted automatically.
D25: Category field | E25: The source dataset does not contain a product category field; product analysis uses StockCode and Description.
... D27: Caveat | E27: Cancellation and return treatment is explicit and conservative, but does not replace accounting reconciliation. Inspect Data Quality and Returns & Cancellations before using totals externally.

Sheet Transaction Data
B1: PROJECT NAVIGATION | D1: TRANSACTION DATA | PREVIEW
B3: 1 · Dashboard | D3: Preview of first 1,000 source rows. All 541,909 source rows were used to calculate the analysis sheets. The complete original file is included separately as Online Retail.xlsx.
B4: 2 · Sales Analysis | D4: InvoiceNo | E4: StockCode | F4: Description | G4: Quantity | H4: InvoiceDate | I4: UnitPrice | J4: CustomerID | K4: Country | L4: LineValue | M4: InvoiceType | N4: Year | O4: Month | P4: Quarter | Q4: DayOfWeek | R4: Hour | S4: IsCancellation | T4: IsPositiveSale | U4: GrossSales | V4: ReversalValue | W4: NetSales
B5: 3 · Monthly Analysis | D5: 536365 | E5: 85123A | F5: WHITE HANGING HEART T-LIGHT HOLDER | G5: 6 | H5: 40513.351 | I5: 2.55 | J5: 17850 | K5: United Kingdom | L5: 15.3 | M5: Sale / positive quantity | N5: 2010 | O5: 2010-12 | P5: 2010Q4 | Q5: Wednesday | R5: 8 | S5: FALSE | T5: TRUE | U5: =IF(T5,L5,0) -> 15.3 | V5: 0 | W5: 15.3
B6: 4 · Country Analysis | D6: 536365 | E6: 71053 | F6: WHITE METAL LANTERN | G6: 6 | H6: 40513.351 | I6: 3.39 | J6: 17850 | K6: United Kingdom | L6: 20.34 | M6: Sale / positive quantity | N6: 2010 | O6: 2010-12 | P6: 2010Q4 | Q6: Wednesday | R6: 8 | S6: FALSE | T6: TRUE | U6: =IF(T6,L6,0) -> 20.34 | V6: 0 | W6: 20.34
B7: 5 · Product Analysis | D7: 536365 | E7: 84406B | F7: CREAM CUPID HEARTS COAT HANGER | G7: 8 | H7: 40513.351 | I7: 2.75 | J7: 17850 | K7: United Kingdom | L7: 22 | M7: Sale / positive quantity | N7: 2010 | O7: 2010-12 | P7: 2010Q4 | Q7: Wednesday | R7: 8 | S7: FALSE | T7: TRUE | U7: =IF(T7,L7,0) -> 22 | V7: 0 | W7: 22
B8: 6 · Customer Analysis | D8: 536365 | E8: 84029G | F8: KNITTED UNION FLAG HOT WATER BOTTLE | G8: 6 | H8: 40513.351 | I8: 3.39 | J8: 17850 | K8: United Kingdom | L8: 20.34 | M8: Sale / positive quantity | N8: 2010 | O8: 2010-12 | P8: 2010Q4 | Q8: Wednesday | R8: 8 | S8: FALSE | T8: TRUE | U8: =IF(T8,L8,0) -> 20.34 | V8: 0 | W8: 20.34
B9: 7 · Returns & Cancellations | D9: 536365 | E9: 84029E | F9: RED WOOLLY HOTTIE WHITE HEART. | G9: 6 | H9: 40513.351 | I9: 3.39 | J9: 17850 | K9: United Kingdom | L9: 20.34 | M9: Sale / positive quantity | N9: 2010 | O9: 2010-12 | P9: 2010Q4 | Q9: Wednesday | R9: 8 | S9: FALSE | T9: TRUE | U9: =IF(T9,L9,0) -> 20.34 | V9: 0 | W9: 20.34
B10: 8 · Time Analysis | D10: 536365 | E10: 22752 | F10: SET 7 BABUSHKA NESTING BOXES | G10: 2 | H10: 40513.351 | I10: 7.65 | J10: 17850 | K10: United Kingdom | L10: 15.3 | M10: Sale / positive quantity | N10: 2010 | O10: 2010-12 | P10: 2010Q4 | Q10: Wednesday | R10: 8 | S10: FALSE | T10: TRUE | U10: =IF(T10,L10,0) -> 15.3 | V10: 0 | W10: 15.3
B11: 9 · Data Quality | D11: 536365 | E11: 21730 | F11: GLASS STAR FROSTED T-LIGHT HOLDER | G11: 6 | H11: 40513.351 | I11: 4.25 | J11: 17850 | K11: United Kingdom | L11: 25.5 | M11: Sale / positive quantity | N11: 2010 | O11: 2010-12 | P11: 2010Q4 | Q11: Wednesday | R11: 8 | S11: FALSE | T11: TRUE | U11: =IF(T11,L11,0) -> 25.5 | V11: 0 | W11: 25.5
B12: 10 · Data Dictionary | D12: 536366 | E12: 22633 | F12: HAND WARMER UNION JACK | G12: 6 | H12: 40513.353 | I12: 1.85 | J12: 17850 | K12: United Kingdom | L12: 11.1 | M12: Sale / positive quantity | N12: 2010 | O12: 2010-12 | P12: 2010Q4 | Q12: Wednesday | R12: 8 | S12: FALSE | T12: TRUE | U12: =IF(T12,L12,0) -> 11.1 | V12: 0 | W12: 11.1
B13: 11 · Transaction Data | D13: 536366 | E13: 22632 | F13: HAND WARMER RED POLKA DOT | G13: 6 | H13: 40513.353 | I13: 1.85 | J13: 17850 | K13: United Kingdom | L13: 11.1 | M13: Sale / positive quantity | N13: 2010 | O13: 2010-12 | P13: 2010Q4 | Q13: Wednesday | R13: 8 | S13: FALSE | T13: TRUE | U13: =IF(T13,L13,0) -> 11.1 | V13: 0 | W13: 11.1
D14: 536367 | E14: 84879 | F14: ASSORTED COLOUR BIRD ORNAMENT | G14: 32 | H14: 40513.357 | I14: 1.69 | J14: 13047 | K14: United Kingdom | L14: 54.08 | M14: Sale / positive quantity | N14: 2010 | O14: 2010-12 | P14: 2010Q4 | Q14: Wednesday | R14: 8 | S14: FALSE | T14: TRUE | U14: =IF(T14,L14,0) -> 54.08 | V14: 0 | W14: 54.08
D15: 536367 | E15: 22745 | F15: POPPY'S PLAYHOUSE BEDROOM | G15: 6 | H15: 40513.357 | I15: 2.1 | J15: 13047 | K15: United Kingdom | L15: 12.6 | M15: Sale / positive quantity | N15: 2010 | O15: 2010-12 | P15: 2010Q4 | Q15: Wednesday | R15: 8 | S15: FALSE | T15: TRUE | U15: =IF(T15,L15,0) -> 12.6 | V15: 0 | W15: 12.6
D16: 536367 | E16: 22748 | F16: POPPY'S PLAYHOUSE KITCHEN | G16: 6 | H16: 40513.357 | I16: 2.1 | J16: 13047 | K16: United Kingdom | L16: 12.6 | M16: Sale / positive quantity | N16: 2010 | O16: 2010-12 | P16: 2010Q4 | Q16: Wednesday | R16: 8 | S16: FALSE | T16: TRUE | U16: =IF(T16,L16,0) -> 12.6 | V16: 0 | W16: 12.6
D17: 536367 | E17: 22749 | F17: FELTCRAFT PRINCESS CHARLOTTE DOLL | G17: 8 | H17: 40513.357 | I17: 3.75 | J17: 13047 | K17: United Kingdom | L17: 30 | M17: Sale / positive quantity | N17: 2010 | O17: 2010-12 | P17: 2010Q4 | Q17: Wednesday | R17: 8 | S17: FALSE | T17: TRUE | U17: =IF(T17,L17,0) -> 30 | V17: 0 | W17: 30
D18: 536367 | E18: 22310 | F18: IVORY KNITTED MUG COSY | G18: 6 | H18: 40513.357 | I18: 1.65 | J18: 13047 | K18: United Kingdom | L18: 9.9 | M18: Sale / positive quantity | N18: 2010 | O18: 2010-12 | P18: 2010Q4 | Q18: Wednesday | R18: 8 | S18: FALSE | T18: TRUE | U18: =IF(T18,L18,0) -> 9.9 | V18: 0 | W18: 9.9
D19: 536367 | E19: 84969 | F19: BOX OF 6 ASSORTED COLOUR TEASPOONS | G19: 6 | H19: 40513.357 | I19: 4.25 | J19: 13047 | K19: United Kingdom | L19: 25.5 | M19: Sale / positive quantity | N19: 2010 | O19: 2010-12 | P19: 2010Q4 | Q19: Wednesday | R19: 8 | S19: FALSE | T19: TRUE | U19: =IF(T19,L19,0) -> 25.5 | V19: 0 | W19: 25.5
D20: 536367 | E20: 22623 | F20: BOX OF VINTAGE JIGSAW BLOCKS | G20: 3 | H20: 40513.357 | I20: 4.95 | J20: 13047 | K20: United Kingdom | L20: 14.85 | M20: Sale / positive quantity | N20: 2010 | O20: 2010-12 | P20: 2010Q4 | Q20: Wednesday | R20: 8 | S20: FALSE | T20: TRUE | U20: =IF(T20,L20,0) -> 14.85 | V20: 0 | W20: 14.85
D21: 536367 | E21: 22622 | F21: BOX OF VINTAGE ALPHABET BLOCKS | G21: 2 | H21: 40513.357 | I21: 9.95 | J21: 13047 | K21: United Kingdom | L21: 19.9 | M21: Sale / positive quantity | N21: 2010 | O21: 2010-12 | P21: 2010Q4 | Q21: Wednesday | R21: 8 | S21: FALSE | T21: TRUE | U21: =IF(T21,L21,0) -> 19.9 | V21: 0 | W21: 19.9
D22: 536367 | E22: 21754 | F22: HOME BUILDING BLOCK WORD | G22: 3 | H22: 40513.357 | I22: 5.95 | J22: 13047 | K22: United Kingdom | L22: 17.85 | M22: Sale / positive quantity | N22: 2010 | O22: 2010-12 | P22: 2010Q4 | Q22: Wednesday | R22: 8 | S22: FALSE | T22: TRUE | U22: =IF(T22,L22,0) -> 17.85 | V22: 0 | W22: 17.85
D23: 536367 | E23: 21755 | F23: LOVE BUILDING BLOCK WORD | G23: 3 | H23: 40513.357 | I23: 5.95 | J23: 13047 | K23: United Kingdom | L23: 17.85 | M23: Sale / positive quantity | N23: 2010 | O23: 2010-12 | P23: 2010Q4 | Q23: Wednesday | R23: 8 | S23: FALSE | T23: TRUE | U23: =IF(T23,L23,0) -> 17.85 | V23: 0 | W23: 17.85
D24: 536367 | E24: 21777 | F24: RECIPE BOX WITH METAL HEART | G24: 4 | H24: 40513.357 | I24: 7.95 | J24: 13047 | K24: United Kingdom | L24: 31.8 | M24: Sale / positive quantity | N24: 2010 | O24: 2010-12 | P24: 2010Q4 | Q24: Wednesday | R24: 8 | S24: FALSE | T24: TRUE | U24: =IF(T24,L24,0) -> 31.8 | V24: 0 | W24: 31.8
D25: 536367 | E25: 48187 | F25: DOORMAT NEW ENGLAND | G25: 4 | H25: 40513.357 | I25: 7.95 | J25: 13047 | K25: United Kingdom | L25: 31.8 | M25: Sale / positive quantity | N25: 2010 | O25: 2010-12 | P25: 2010Q4 | Q25: Wednesday | R25: 8 | S25: FALSE | T25: TRUE | U25: =IF(T25,L25,0) -> 31.8 | V25: 0 | W25: 31.8
... D626: 536412 | E626: 20750 | F626: RED RETROSPOT MINI CASES | G626: 1 | H626: 40513.492 | I626: 7.95 | J626: 17920 | K626: United Kingdom | L626: 7.95 | M626: Sale / positive quantity | N626: 2010 | O626: 2010-12 | P626: 2010Q4 | Q626: Wednesday | R626: 11 | S626: FALSE | T626: TRUE | U626: =IF(T626,L626,0) -> 7.95 | V626: 0 | W626: 7.95
D627: 536414 | E627: 22139 | G627: 56 | H627: 40513.494 | I627: 0 | K627: United Kingdom | L627: 0 | M627: Sale / positive quantity | N627: 2010 | O627: 2010-12 | P627: 2010Q4 | Q627: Wednesday | R627: 11 | S627: FALSE | T627: FALSE | U627: =IF(T627,L627,0) -> 0 | V627: 0 | W627: 0
D628: 536415 | E628: 22952 | F628: 60 CAKE CASES VINTAGE CHRISTMAS | G628: 10 | H628: 40513.498 | I628: 0.55 | J628: 12838 | K628: United Kingdom | L628: 5.5 | M628: Sale / positive quantity | N628: 2010 | O628: 2010-12 | P628: 2010Q4 | Q628: Wednesday | R628: 11 | S628: FALSE | T628: TRUE | U628: =IF(T628,L628,0) -> 5.5 | V628: 0 | W628: 5.5
D629: 536415 | E629: 22910 | F629: PAPER CHAIN KIT VINTAGE CHRISTMAS | G629: 5 | H629: 40513.498 | I629: 2.95 | J629: 12838 | K629: United Kingdom | L629: 14.75 | M629: Sale / positive quantity | N629: 2010 | O629: 2010-12 | P629: 2010Q4 | Q629: Wednesday | R629: 11 | S629: FALSE | T629: TRUE | U629: =IF(T629,L629,0) -> 14.75 | V629: 0 | W629: 14.75
D630: 536415 | E630: 22739 | F630: RIBBON REEL CHRISTMAS SOCK BAUBLE | G630: 3 | H630: 40513.498 | I630: 1.65 | J630: 12838 | K630: United Kingdom | L630: 4.95 | M630: Sale / positive quantity | N630: 2010 | O630: 2010-12 | P630: 2010Q4 | Q630: Wednesday | R630: 11 | S630: FALSE | T630: TRUE | U630: =IF(T630,L630,0) -> 4.95 | V630: 0 | W630: 4.95
D631: 536415 | E631: 22738 | F631: RIBBON REEL SNOWY VILLAGE | G631: 3 | H631: 40513.498 | I631: 1.65 | J631: 12838 | K631: United Kingdom | L631: 4.95 | M631: Sale / positive quantity | N631: 2010 | O631: 2010-12 | P631: 2010Q4 | Q631: Wednesday | R631: 11 | S631: FALSE | T631: TRUE | U631: =IF(T631,L631,0) -> 4.95 | V631: 0 | W631: 4.95
D632: 536415 | E632: 22736 | F632: RIBBON REEL MAKING SNOWMEN | G632: 3 | H632: 40513.498 | I632: 1.65 | J632: 12838 | K632: United Kingdom | L632: 4.95 | M632: Sale / positive quantity | N632: 2010 | O632: 2010-12 | P632: 2010Q4 | Q632: Wednesday | R632: 11 | S632: FALSE | T632: TRUE | U632: =IF(T632,L632,0) -> 4.95 | V632: 0 | W632: 4.95
D633: 536415 | E633: 22909 | F633: SET OF 20 VINTAGE CHRISTMAS NAPKINS | G633: 5 | H633: 40513.498 | I633: 0.85 | J633: 12838 | K633: United Kingdom | L633: 4.25 | M633: Sale / positive quantity | N633: 2010 | O633: 2010-12 | P633: 2010Q4 | Q633: Wednesday | R633: 11 | S633: FALSE | T633: TRUE | U633: =IF(T633,L633,0) -> 4.25 | V633: 0 | W633: 4.25
D634: 536415 | E634: 35591T | F634: TURQUOISE CHRISTMAS TREE | G634: 2 | H634: 40513.498 | I634: 1.25 | J634: 12838 | K634: United Kingdom | L634: 2.5 | M634: Sale / positive quantity | N634: 2010 | O634: 2010-12 | P634: 2010Q4 | Q634: Wednesday | R634: 11 | S634: FALSE | T634: TRUE | U634: =IF(T634,L634,0) -> 2.5 | V634: 0 | W634: 2.5
D635: 536415 | E635: 22186 | F635: RED STAR CARD HOLDER | G635: 5 | H635: 40513.498 | I635: 2.95 | J635: 12838 | K635: United Kingdom | L635: 14.75 | M635: Sale / positive quantity | N635: 2010 | O635: 2010-12 | P635: 2010Q4 | Q635: Wednesday | R635: 11 | S635: FALSE | T635: TRUE | U635: =IF(T635,L635,0) -> 14.75 | V635: 0 | W635: 14.75
D636: 536415 | E636: 22695 | F636: WICKER WREATH SMALL | G636: 3 | H636: 40513.498 | I636: 1.45 | J636: 12838 | K636: United Kingdom | L636: 4.35 | M636: Sale / positive quantity | N636: 2010 | O636: 2010-12 | P636: 2010Q4 | Q636: Wednesday | R636: 11 | S636: FALSE | T636: TRUE | U636: =IF(T636,L636,0) -> 4.35 | V636: 0 | W636: 4.35
D637: 536415 | E637: 22470 | F637: HEART OF WICKER LARGE | G637: 1 | H637: 40513.498 | I637: 2.95 | J637: 12838 | K637: United Kingdom | L637: 2.95 | M637: Sale / positive quantity | N637: 2010 | O637: 2010-12 | P637: 2010Q4 | Q637: Wednesday | R637: 11 | S637: FALSE | T637: TRUE | U637: =IF(T637,L637,0) -> 2.95 | V637: 0 | W637: 2.95
D638: 536415 | E638: 22580 | F638: ADVENT CALENDAR GINGHAM SACK | G638: 1 | H638: 40513.498 | I638: 5.95 | J638: 12838 | K638: United Kingdom | L638: 5.95 | M638: Sale / positive quantity | N638: 2010 | O638: 2010-12 | P638: 2010Q4 | Q638: Wednesday | R638: 11 | S638: FALSE | T638: TRUE | U638: =IF(T638,L638,0) -> 5.95 | V638: 0 | W638: 5.95
D639: 536415 | E639: 22469 | F639: HEART OF WICKER SMALL | G639: 5 | H639: 40513.498 | I639: 1.65 | J639: 12838 | K639: United Kingdom | L639: 8.25 | M639: Sale / positive quantity | N639: 2010 | O639: 2010-12 | P639: 2010Q4 | Q639: Wednesday | R639: 11 | S639: FALSE | T639: TRUE | U639: =IF(T639,L639,0) -> 8.25 | V639: 0 | W639: 8.25
... D1004: 536520 | E1004: 21358 | F1004: TOAST ITS - HAPPY BIRTHDAY | G1004: 2 | H1004: 40513.53 | I1004: 1.25 | J1004: 14729 | K1004: United Kingdom | L1004: 2.5 | M1004: Sale / positive quantity | N1004: 2010 | O1004: 2010-12 | P1004: 2010Q4 | Q1004: Wednesday | R1004: 12 | S1004: FALSE | T1004: TRUE | U1004: =IF(T1004,L1004,0) -> 2.5 | V1004: 0 | W1004: 2.5
D1006: GrossSales (column U) was overwritten by the old navigation panel; it has been restored as =IF(IsPositiveSale, LineValue, 0), which matches NetSales = GrossSales - ReversalValue on every row.
